Workbook

Sheet Hướng dẫn
A1: DANH MỤC TEST CASE - HỆ THỐNG QUẢN LÝ THƯ VIỆN
A3: Cách dùng | B3: Mở sheet "Test case", chạy từng dòng theo cột "Các bước thực hiện" và so với "Kết quả dự kiến". Sau đó điền các cột nền vàng (đúng các thành phần thầy yêu cầu: đầu ra thực tế, kết quả pass/fail, đề xuất và mô tả quá trình fix lỗi). Sheet "Tổng hợp" tự tính số lượng Pass/Fail theo nhóm, không cần sửa.
A4: Ô cần điền (nền vàng) | B4: Cột G "Đầu ra thực tế", cột H "Kết quả test (Pass/Fail)" (chọn trong danh sách), cột I "Đề xuất và mô tả quá trình fix lỗi", cột J "Ghi chú / tên file ảnh". Các cột còn lại là nội dung test đã soạn sẵn (mục tiêu, dữ liệu đầu vào và ràng buộc, đầu ra dự kiến).
A5: Thứ tự nên chạy | B5: Chạy các dòng ưu tiên "Cao" trước (cột K, lọc bằng bộ lọc ở dòng tiêu đề). Dòng Fail: ghi lỗi, sửa code, chạy lại và cập nhật kết quả. Báo cáo cần mô tả quá trình sửa lỗi.
A7: Ví dụ cách điền một dòng
A8: Mã TC / Mục tiêu | B8: DN-03 / Sai mật khẩu
A9: Đầu ra thực tế (G) | B9: Hiện thông báo "Email hoặc mật khẩu không đúng", vẫn ở trang đăng nhập.
A10: Kết quả test (H) | B10: Pass
A11: Đề xuất, mô tả fix lỗi (I) | B11: Không có. (Nếu Fail: "Thông báo hiện bằng tiếng Anh. Sửa: thêm khóa login.err.invalid vào Resources/SharedResource.resx. Chạy lại: Pass.")
A12: Ghi chú / ảnh (J) | B12: dn-03.png (ảnh chụp màn hình dán vào báo cáo mục 4.4)
A14: Dữ liệu mẫu và điều kiện chung
A15: Tài khoản Admin | B15: admin@library.local / Admin@123
A16: Tài khoản khách mẫu | B16: khach@library.local / Khach@123 (hồ sơ TV000001, SĐT 0901234567, thẻ "Thường - 1 tháng": 3 sách, 14 ngày, gia hạn 1 lần, cọc 100.000 đ)
A17: Gói thẻ mẫu | B17: Thường - 1 tháng (50.000 đ, cọc 100.000 đ); Thường - 6 tháng (250.000 đ); VIP - 1 năm (400.000 đ, cọc 200.000 đ, 8 sách, 30 ngày, gia hạn 2 lần)
A18: Sách mẫu | B18: 21 đầu sách, 51 bản sao. Mã vạch BC{số sách 4 số}{số bản 2 số}, ví dụ BC000101 (Cho tôi xin một vé đi tuổi thơ: thuê 5.000 đ, giá đền 80.000 đ), BC000201 (Mắt biếc), BC001602 (Clean Code, bản chỉ đọc tại chỗ).
A19: Mức phạt trả trễ | B19: 2.000 đ/cuốn/ngày, tối đa bằng giá đền của sách (cấu hình Library:LateFeePerDay trong appsettings.json).
A20: Trạng thái ban đầu | B20: Nên chạy trên database mới seed. Nhiều test thay đổi dữ liệu nên chạy theo thứ tự trong từng nhóm; khi cần có thể tạo lại khách mới.
A22: Lệnh SQL hay dùng
A23: Xem dòng mượn chưa trả | B23: SELECT i.Id, c.Barcode, i.DueDate, i.RenewCount FROM LoanItems i JOIN BookCopies c ON c.Id = i.BookCopyId WHERE i.ReturnedAt IS NULL;
A24: Làm sách quá hạn 5 ngày | B24: UPDATE LoanItems SET DueDate = DATEADD(day, -5, CAST(GETDATE() AS date)) WHERE Id = <Id dòng mượn>;
A25: Mở khóa tài khoản | B25: UPDATE AspNetUsers SET LockoutEnd = NULL, AccessFailedCount = 0 WHERE Email = 'khach@library.local';
A26: Vô hiệu hóa / bật lại | B26: UPDATE AspNetUsers SET IsActive = 0 WHERE Email = 'khach@library.local'; (bật lại: IsActive = 1)
A27: Thẻ sắp hết hạn | B27: UPDATE Memberships SET EndDate = DATEADD(day, 5, CAST(GETDATE() AS date)) WHERE Id = <Id thẻ>;
A28: Kiểm tra mượn trùng bản | B28: SELECT BookCopyId, COUNT(*) FROM LoanItems WHERE ReturnedAt IS NULL GROUP BY BookCopyId HAVING COUNT(*) > 1; (phải ra 0 dòng)

Sheet Test case
A1: DANH MỤC TEST CASE
A2: Nền vàng = ô bạn điền sau khi chạy test. Chọn Pass/Fail ở cột H (Kết quả test). Xem sheet "Hướng dẫn" để biết dữ liệu mẫu và lệnh SQL.
A4: Mã TC | B4: Nhóm chức năng | C4: Mục tiêu test | D4: Các bước thực hiện | E4: Dữ liệu đầu vào, các ràng buộc | F4: Đầu ra dự kiến | G4: Đầu ra thực tế | H4: Kết quả test (Pass/Fail) | I4: Đề xuất và mô tả quá trình fix lỗi | J4: Ghi chú / ảnh | K4: Ưu tiên
A5: DN-01 | B5: Đăng nhập, đăng ký, phân quyền | C5: Đăng nhập Admin hợp lệ | D5: 1. Mở /Identity/Account/Login 2. Nhập email, mật khẩu 3. Bấm Đăng nhập | E5: admin@library.local / Admin@123 | F5: Chuyển tới /Admin, thấy Bảng điều khiển. | G5: Đăng nhập thành công, chuyển tới /Admin, thấy Bảng điều khiển. | H5: Pass | J5: Mình chạy 19/10/2026 trên localhost:7105 | K5: Cao
A6: DN-02 | B6: Đăng nhập, đăng ký, phân quyền | C6: Đăng nhập khách hàng hợp lệ | D6: Như DN-01 với tài khoản khách | E6: khach@library.local / Khach@123 | F6: Chuyển tới /My (Tài khoản của tôi). | G6: Đăng nhập thành công, chuyển tới /My (Tổng quan tài khoản). | H6: Pass | J6: Mình chạy 19/10/2026 trên localhost:7105 | K6: Cao
A7: DN-03 | B7: Đăng nhập, đăng ký, phân quyền | C7: Sai mật khẩu | D7: Đăng nhập admin với mật khẩu sai | E7: admin@library.local / Sai@123 | F7: Báo "Email hoặc mật khẩu không đúng", không đăng nhập. | G7: Ở lại trang đăng nhập, báo 'Email hoặc mật khẩu không đúng.' | H7: Pass | J7: Mình chạy 19/10/2026 trên localhost:7105 | K7: Cao
A8: DN-04 | B8: Đăng nhập, đăng ký, phân quyền | C8: Email chưa đăng ký không bị lộ | D8: Đăng nhập với email không tồn tại | E8: khong.co@library.local / Abc@1234 | F8: Cùng thông báo chung như DN-03 (không cho biết email có tồn tại hay không). | G8: Thông báo giống hệt DN-03, không lộ email nào đã đăng ký. | H8: Pass | J8: Mình chạy 19/10/2026 trên localhost:7105 | K8: Trung bình
A9: DN-05 | B9: Đăng nhập, đăng ký, phân quyền | C9: Khóa tài khoản khi sai mật khẩu nhiều lần | D9: 1. Đăng nhập khach@ với mật khẩu sai 5 lần liên tiếp 2. Nhập lại đúng mật khẩu 3. Kiểm tra SQL: SELECT Email, AccessFailedCount, LockoutEnd FROM AspNetUsers | E9: Ràng buộc: tối đa 5 lần sai, khóa 5 phút | F9: Từ lần sai thứ 5 báo "khóa tạm thời ... 5 phút". Nhập đúng vẫn bị từ chối. LockoutEnd có giá trị. Sau khi test chạy: UPDATE AspNetUsers SET LockoutEnd=NULL, AccessFailedCount=0 WHERE Email='khach@library.local'. | G9: Lần sai thứ 5 báo 'Tài khoản bị khóa tạm thời... thử lại sau 5 phút'; đăng nhập đúng mật khẩu sau đó vẫn bị từ chối. | H9: Pass | J9: Mình chạy 19/10/2026 trên localhost:7105 | K9: Cao
A10: DN-06 | B10: Đăng nhập, đăng ký, phân quyền | C10: Tài khoản bị vô hiệu hóa không đăng nhập được | D10: 1. UPDATE AspNetUsers SET IsActive=0 WHERE Email='khach@library.local' 2. Đăng nhập đúng mật khẩu 3. Trả lại IsActive=1 | E10: khach@library.local / Khach@123 | F10: Báo tài khoản đã bị vô hiệu hóa, không vào được. | G10: Sau khi đặt IsActive = 0, đăng nhập báo 'Tài khoản đã bị vô hiệu hóa. Vui lòng liên hệ thư viện.' | H10: Pass | J10: Cần chạy UPDATE AspNetUsers SET IsActive = 1 để bật lại tài khoản khách mẫu | K10: Trung bình
A11: DN-07 | B11: Đăng nhập, đăng ký, phân quyền | C11: Chưa đăng nhập vào khu Admin | D11: Mở /Admin khi chưa đăng nhập | E11: - | F11: Chuyển sang trang đăng nhập (có returnUrl). | G11: /Admin chuyển về /Identity/Account/Login kèm ReturnUrl. | H11: Pass | J11: Mình chạy 19/10/2026 trên localhost:7105 | K11: Cao
A12: DN-08 | B12: Đăng nhập, đăng ký, phân quyền | C12: Chưa đăng nhập vào khu khách hàng | D12: Mở /My khi chưa đăng nhập | E12: - | F12: Chuyển sang trang đăng nhập. | G12: /My chuyển về trang đăng nhập. | H12: Pass | J12: Mình chạy 19/10/2026 trên localhost:7105 | K12: Cao
A13: DN-09 | B13: Đăng nhập, đăng ký, phân quyền | C13: Khách hàng không vào được khu Admin | D13: Đăng nhập khách, mở /Admin | E13: khach@library.local | F13: Bị từ chối truy cập (Access denied). | G13: Khách vào /Admin và /Admin/Books đều bị chuyển tới /Identity/Account/AccessDenied. | H13: Pass | I13: Trang Access denied đang tiếng Anh, xem mục 3 trong tổng hợp lỗi. | J13: Mình chạy 19/10/2026 trên localhost:7105 | K13: Cao
A14: DN-10 | B14: Đăng nhập, đăng ký, phân quyền | C14: Admin không vào được khu khách hàng | D14: Đăng nhập admin, mở /My | E14: admin@library.local | F14: Bị từ chối truy cập. | G14: Admin vào /My bị chuyển tới /Identity/Account/AccessDenied. | H14: Pass | I14: Trang Access denied đang tiếng Anh, xem mục 3 trong tổng hợp lỗi. | J14: Mình chạy 19/10/2026 trên localhost:7105 | K14: Trung bình
A15: DN-11 | B15: Đăng nhập, đăng ký, phân quyền | C15: Đăng ký tài khoản mới, SĐT chưa có hồ sơ | D15: 1. /Identity/Account/Register 2. Nhập thông tin, để trống Mã thành viên 3. Bấm Đăng ký | E15: Họ tên: Trần Thị B; email mới; SĐT 0912000111; mật khẩu Abc@1234 (≥ 6 ký tự) | F15: Tạo tài khoản role User, tự tạo hồ sơ khách (mã TV mới), tự đăng nhập, vào /My (chưa có thẻ hiệu lực). | G15: Tạo tài khoản và hồ sơ mới tự động, chuyển tới /My, hiện 'Chưa có thẻ hiệu lực'. | H15: Pass | J15: Mình chạy 19/10/2026 trên localhost:7105 | K15: Cao
A16: DN-12 | B16: Đăng nhập, đăng ký, phân quyền | C16: Chặn chiếm hồ sơ bằng SĐT | D16: Đăng ký với SĐT của hồ sơ đã có, không nhập mã | E16: SĐT 0901234567 (khách mẫu) | F16: Từ chối, báo SĐT đã có hồ sơ và hướng dẫn nhập mã thành viên. | G16: Từ chối: 'Số điện thoại này đã có hồ sơ tại thư viện. Hãy nhập mã thành viên... để liên kết'. | H16: Pass | J16: Mình chạy 19/10/2026 trên localhost:7105 | K16: Cao
A17: DN-13 | B17: Đăng nhập, đăng ký, phân quyền | C17: Liên kết hồ sơ tạo tại quầy (mã + SĐT khớp) | D17: 1. Admin tạo khách SĐT 0912000222, ghi mã TV 2. Đăng ký tài khoản bằng đúng mã và SĐT đó | E17: Mã TV vừa tạo + SĐT 0912000222 | F17: Đăng ký thành công, hồ sơ được liên kết (Admin thấy "Tài khoản web" có email); nếu đã bán thẻ thì /My thấy thẻ. | G17: Liên kết thành công với hồ sơ TV000004 (Lê Văn C), chuyển tới /My. | H17: Pass | J17: Mình chạy 19/10/2026 trên localhost:7105 | K17: Cao
A18: DN-14 | B18: Đăng nhập, đăng ký, phân quyền | C18: Mã đúng nhưng SĐT sai | D18: Đăng ký với mã TV hợp lệ và SĐT khác | E18: Mã TV000001 + SĐT 0999999999 | F18: Từ chối: mã và số điện thoại không khớp. | G18: Từ chối: 'Mã thành viên và số điện thoại không khớp, hoặc hồ sơ này đã được liên kết...'. | H18: Pass | J18: Mình chạy 19/10/2026 trên localhost:7105 | K18: Trung bình
A19: DN-15 | B19: Đăng nhập, đăng ký, phân quyền | C19: Không liên kết hồ sơ đã có tài khoản | D19: Đăng ký với mã và SĐT của hồ sơ đã liên kết | E19: TV000001 + 0901234567 | F19: Từ chối: hồ sơ đã được liên kết với tài khoản khác. | G19: Từ chối với cùng thông báo chung, không tiết lộ lý do chi tiết. | H19: Pass | J19: Mình chạy 19/10/2026 trên localhost:7105 | K19: Trung bình
A20: DN-16 | B20: Đăng nhập, đăng ký, phân quyền | C20: Email đăng ký trùng | D20: Đăng ký với email đã tồn tại | E20: khach@library.local | F20: Báo lỗi email đã được sử dụng, không tạo tài khoản. | G20: Bị từ chối nhưng thông báo tiếng Anh và lặp hai lần: "Username 'khach@library.local' is already taken. Email '...' is already taken." | H20: Fail | I20: Trước khi gọi CreateAsync, kiểm tra email bằng UserManager.FindByEmailAsync; nếu có thì thêm một lỗi tiếng Việt duy nhất (khóa resx mới). Hoặc viết lớp kế thừa IdentityErrorDescriber (dịch DuplicateUserName, DuplicateEmail, mật khẩu yếu) và đăng ký bằng .AddErrorDescriber<...>(). | J20: Mình chạy 19/10/2026 trên localhost:7105 | K20: Trung bình
A21: DN-17 | B21: Đăng nhập, đăng ký, phân quyền | C21: Kiểm tra dữ liệu form đăng ký | D21: Bỏ trống các ô, nhập mật khẩu 3 ký tự, mật khẩu xác nhận khác | E21: Mật khẩu "abc", xác nhận "abd"; SĐT "123" | F21: Hiện lỗi từng trường: bắt buộc nhập, mật khẩu ≥ 6 ký tự, xác nhận không khớp, SĐT không hợp lệ. | G21: Báo 5 lỗi tiếng Việt: họ tên, email, SĐT sai định dạng, mật khẩu < 6 ký tự, xác nhận không khớp. | H21: Pass | J21: Mình chạy 19/10/2026 trên localhost:7105 | K21: Trung bình
A22: KS-01 | B22: Kho sách | C22: Thêm tác giả hợp lệ | D22: Admin > Tác giả > Thêm tác giả > nhập tên > Lưu | E22: Tên: Tố Hữu | F22: Thêm thành công, hiện trong danh sách, thông báo xanh. | G22: Đã thêm tác giả, quay về danh sách. | H22: Pass | J22: Mình chạy 19/10/2026 trên localhost:7105 | K22: Cao
A23: KS-02 | B23: Kho sách | C23: Tên tác giả bắt buộc | D23: Thêm tác giả để trống tên | E23: Tên: (trống) | F23: Báo "Vui lòng nhập tên tác giả", không lưu. | G23: Báo 'Vui lòng nhập tên tác giả'. | H23: Pass | J23: Mình chạy 19/10/2026 trên localhost:7105 | K23: Trung bình
A24: KS-03 | B24: Kho sách | C24: Không xóa tác giả còn sách | D24: Xóa tác giả "Nguyễn Nhật Ánh" | E24: Tác giả có 3 sách | F24: Bị chặn, báo còn sách của tác giả này. | G24: Không xóa được vì tác giả còn sách. | H24: Pass | J24: Bạn chạy thủ công và báo kết quả | K24: Cao
A25: KS-04 | B25: Kho sách | C25: Thể loại không được trùng tên | D25: Thêm thể loại "Thiếu nhi" | E25: Tên đã tồn tại | F25: Báo thể loại đã tồn tại. | G25: Báo 'Thể loại này đã tồn tại.' | H25: Pass | J25: Mình chạy 19/10/2026 trên localhost:7105 | K25: Cao
A26: KS-05 | B26: Kho sách | C26: Thêm đầu sách kèm bản sao, mã vạch tự sinh | D26: Admin > Đầu sách > Thêm sách; nhập đủ thông tin; Số bản sao ban đầu = 2; Lưu | E26: ISBN mới, chọn tác giả và thể loại | F26: Chuyển sang trang chi tiết, có 2 bản sao, mã vạch dạng BC{mã sách 4 số}01, 02, trạng thái Sẵn sàng. | G26: Thêm sách kèm 2 bản sao, mã vạch tự sinh BC002201, BC002202. | H26: Pass | J26: Mình chạy 19/10/2026 trên localhost:7105 | K26: Cao
A27: KS-06 | B27: Kho sách | C27: ISBN không được trùng | D27: Thêm sách với ISBN đã có | E27: ISBN của sách mẫu (ví dụ 9786040000001) | F27: Báo ISBN đã tồn tại. | G27: Báo 'ISBN này đã tồn tại.' | H27: Pass | J27: Mình chạy 19/10/2026 trên localhost:7105 | K27: Cao
A28: KS-07 | B28: Kho sách | C28: Bắt buộc chọn tác giả và thể loại | D28: Thêm sách, để "-- Chọn tác giả --" | E28: AuthorId = 0 | F28: Báo "Vui lòng chọn tác giả" (và thể loại). | G28: Báo 'Vui lòng chọn tác giả' và 'Vui lòng chọn thể loại'. | H28: Pass | J28: Mình chạy 19/10/2026 trên localhost:7105 | K28: Trung bình
A29: KS-08 | B29: Kho sách | C29: Từ chối ảnh bìa sai định dạng | D29: Chọn file .pdf làm ảnh bìa | E29: File .pdf | F29: Báo chỉ chấp nhận ảnh .jpg, .jpeg, .png, .webp. | G29: Báo 'Chỉ chấp nhận ảnh .jpg, .jpeg, .png hoặc .webp.' | H29: Pass | J29: Mình chạy 19/10/2026 trên localhost:7105 | K29: Cao
A30: KS-09 | B30: Kho sách | C30: Từ chối ảnh bìa quá lớn | D30: Chọn ảnh > 2MB | E30: Ảnh 3MB | F30: Báo ảnh bìa tối đa 2MB. | G30: Báo 'Ảnh bìa tối đa 2MB.' | H30: Pass | J30: Mình chạy 19/10/2026 trên localhost:7105 | K30: Cao
A31: KS-10 | B31: Kho sách | C31: Upload ảnh bìa hợp lệ | D31: Chọn ảnh .jpg dưới 2MB, Lưu | E31: Ảnh 200KB | F31: Ảnh hiện ở danh sách, chi tiết (Admin) và trang công khai; file nằm trong wwwroot/covers. | G31: Cập nhật thành công, ảnh lưu dạng /covers/<GUID>.jpg và tải được (200, image/jpeg). | H31: Pass | J31: Dùng ảnh JPG 41 KB làm ảnh hợp lệ | K31: Cao
A32: KS-11 | B32: Kho sách | C32: Thêm bản sao, mã vạch không trùng | D32: Chi tiết sách > Thêm bản sao > số lượng 3 | E32: Sách đã có 2 bản | F32: Sinh 3 mã vạch mới nối tiếp (…03, 04, 05), không trùng mã cũ. | G32: Thêm 2 bản BC002203, BC002204; toàn bộ mã vạch của sách không trùng nhau. | H32: Pass | J32: Mình chạy 19/10/2026 trên localhost:7105 | K32: Cao
A33: KS-12 | B33: Kho sách | C33: Đổi bản sao sang Hỏng | D33: Sửa bản sao > Trạng thái = Hỏng | E33: Bản sao đang Sẵn sàng | F33: Lưu thành công; số "Sẵn sàng" của sách giảm 1; công khai không tính bản này. | G33: Bản sao BC002204 chuyển sang Hỏng. | H33: Pass | J33: Mình chạy 19/10/2026 trên localhost:7105 | K33: Trung bình
A34: KS-13 | B34: Kho sách | C34: Không đổi trạng thái bản sao đang mượn | D34: Sửa bản sao đang được mượn | E34: Bản sao Đang mượn | F34: Form chỉ hiện nhãn "Đang mượn", không cho đổi trạng thái. | G34: Giao diện khóa ô trạng thái ('Bản sao đang cho mượn, trả sách tại quầy trước khi đổi'). Khi ép gửi POST, trạng thái vẫn là Đang mượn nhưng hệ thống báo 'Đã cập nhật bản sao'. | H34: Pass | I34: Trong BookCopiesController.Edit (POST): nếu bản sao có dòng mượn chưa trả và trạng thái đổi khác, trả lỗi 'Bản sao đang được mượn, hãy trả sách trước' và không hiện thông báo thành công. Mức độ thấp (dữ liệu không bị sai). | J34: Mình chạy 19/10/2026 trên localhost:7105 | K34: Trung bình
A35: KS-14 | B35: Kho sách | C35: Không xóa sách đã có bản sao | D35: Chi tiết sách có bản sao: thử xóa | E35: Sách mẫu | F35: Không có nút Xóa (hoặc bị chặn); hướng dẫn bỏ "Đang kinh doanh". | G35: Chưa chạy: thao tác xóa dữ liệu. | H35: Chưa test | J35: Bạn tự chạy và báo kết quả | K35: Trung bình
A36: KS-15 | B36: Kho sách | C36: Tìm kiếm, lọc, phân trang danh sách sách (Admin) | D36: 1. Tìm "clean" 2. Lọc thể loại Công nghệ thông tin 3. Xóa lọc, chuyển trang | E36: 21 sách mẫu, 10 sách/trang | F36: Tìm "clean" ra 3 sách; lọc CNTT ra 3 sách; không lọc có 3 trang, bộ lọc được giữ khi chuyển trang. | G36: 22 sách: trang 1 có 10, trang 2 có 10, trang 3 có 2. Tìm 'clean' ra 3, 'harry' ra 2; lọc thể loại đúng. | H36: Pass | J36: Mình chạy 19/10/2026 trên localhost:7105 | K36: Cao
A37: KH-01 | B37: Gói thẻ và khách hàng | C37: Tạo gói thành viên hợp lệ | D37: Admin > Gói thành viên > Thêm gói | E37: Tên: Sinh viên 3 tháng; giá 120.000; 3 tháng; cọc 50.000; 3 sách; 14 ngày; 1 lần gia hạn | F37: Thêm thành công, hiện trong danh sách. | G37: Đã thêm gói thành viên mới. | H37: Pass | J37: Mình chạy 19/10/2026 trên localhost:7105 | K37: Cao
A38: KH-02 | B38: Gói thẻ và khách hàng | C38: Kiểm tra ràng buộc số trong gói | D38: Tạo gói với thời hạn 0 tháng, giá âm | E38: DurationMonths = 0; Price = -1 | F38: Báo lỗi giá trị ngoài khoảng cho phép. | G38: Bị từ chối nhưng thông báo tiếng Anh: 'The field Phí gói must be between 0 and 100000000.' và 'The field Thời hạn (tháng) must be between 1 and 120.' | H38: Pass | I38: Đặt ErrorMessage tiếng Việt (hoặc khóa resx) cho các thuộc tính [Range] trong ViewModel gói thẻ (và sách); kiểm tra lại các [Required], [StringLength] khác có dùng thông báo mặc định không. | J38: Mình chạy 19/10/2026 trên localhost:7105 | K38: Trung bình
A39: KH-03 | B39: Gói thẻ và khách hàng | C39: Không xóa gói đã bán | D39: Xóa gói "Thường - 1 tháng" | E39: Gói đã có thẻ | F39: Bị chặn, hướng dẫn bỏ "Đang bán". | G39: Chưa chạy: thao tác xóa dữ liệu. | H39: Chưa test | J39: Bạn tự chạy và báo kết quả | K39: Trung bình
A40: KH-04 | B40: Gói thẻ và khách hàng | C40: Tạo hồ sơ khách hợp lệ | D40: Admin > Khách hàng > Tạo hồ sơ khách | E40: Họ tên Lê Văn C; SĐT 0912000333 | F40: Mã thành viên tự sinh (TV tăng dần), chuyển sang chi tiết khách. | G40: Tạo hồ sơ TV000004, chuyển tới trang chi tiết khách. | H40: Pass | J40: Mình chạy 19/10/2026 trên localhost:7105 | K40: Cao
A41: KH-05 | B41: Gói thẻ và khách hàng | C41: SĐT sai định dạng | D41: Tạo khách với SĐT 123 | E41: SĐT: 123 | F41: Báo số điện thoại không hợp lệ. | G41: Báo 'Số điện thoại không hợp lệ (ví dụ 0901234567)'. | H41: Pass | J41: Mình chạy 19/10/2026 trên localhost:7105 | K41: Trung bình
...

Sheet Tổng hợp
A1: TỔNG HỢP KẾT QUẢ KIỂM THỬ
A2: Tự tính từ sheet "Test case" (cột Nhóm chức năng và cột Kết quả test). Không cần nhập tay.
A4: Nhóm chức năng | B4: Tổng số | C4: Pass | D4: Fail | E4: Chưa test | F4: Tỷ lệ Pass | G4: Tỷ lệ đã test
A5: Đăng nhập, đăng ký, phân quyền | B5: =COUNTIF('Test case'!$B$5:$B$119,A5) -> 17 | C5: =COUNTIFS('Test case'!$B$5:$B$119,A5,'Test case'!$H$5:$H$119,"Pass") -> 16 | D5: =COUNTIFS('Test case'!$B$5:$B$119,A5,'Test case'!$H$5:$H$119,"Fail") -> 1 | E5: =COUNTIFS('Test case'!$B$5:$B$119,A5,'Test case'!$H$5:$H$119,"Chưa test") -> 0 | F5: =IF(B5=0,0,C5/B5) -> 0.94117647 | G5: =IF(B5=0,0,(C5+D5)/B5) -> 1
A6: Kho sách | B6: =COUNTIF('Test case'!$B$5:$B$119,A6) -> 15 | C6: =COUNTIFS('Test case'!$B$5:$B$119,A6,'Test case'!$H$5:$H$119,"Pass") -> 14 | D6: =COUNTIFS('Test case'!$B$5:$B$119,A6,'Test case'!$H$5:$H$119,"Fail") -> 0 | E6: =COUNTIFS('Test case'!$B$5:$B$119,A6,'Test case'!$H$5:$H$119,"Chưa test") -> 1 | F6: =IF(B6=0,0,C6/B6) -> 0.93333333 | G6: =IF(B6=0,0,(C6+D6)/B6) -> 0.93333333
A7: Gói thẻ và khách hàng | B7: =COUNTIF('Test case'!$B$5:$B$119,A7) -> 12 | C7: =COUNTIFS('Test case'!$B$5:$B$119,A7,'Test case'!$H$5:$H$119,"Pass") -> 11 | D7: =COUNTIFS('Test case'!$B$5:$B$119,A7,'Test case'!$H$5:$H$119,"Fail") -> 0 | E7: =COUNTIFS('Test case'!$B$5:$B$119,A7,'Test case'!$H$5:$H$119,"Chưa test") -> 1 | F7: =IF(B7=0,0,C7/B7) -> 0.91666667 | G7: =IF(B7=0,0,(C7+D7)/B7) -> 0.91666667
A8: Mượn, trả, gia hạn | B8: =COUNTIF('Test case'!$B$5:$B$119,A8) -> 22 | C8: =COUNTIFS('Test case'!$B$5:$B$119,A8,'Test case'!$H$5:$H$119,"Pass") -> 21 | D8: =COUNTIFS('Test case'!$B$5:$B$119,A8,'Test case'!$H$5:$H$119,"Fail") -> 0 | E8: =COUNTIFS('Test case'!$B$5:$B$119,A8,'Test case'!$H$5:$H$119,"Chưa test") -> 1 | F8: =IF(B8=0,0,C8/B8) -> 0.95454545 | G8: =IF(B8=0,0,(C8+D8)/B8) -> 0.95454545
A9: Thu tiền và báo cáo | B9: =COUNTIF('Test case'!$B$5:$B$119,A9) -> 13 | C9: =COUNTIFS('Test case'!$B$5:$B$119,A9,'Test case'!$H$5:$H$119,"Pass") -> 13 | D9: =COUNTIFS('Test case'!$B$5:$B$119,A9,'Test case'!$H$5:$H$119,"Fail") -> 0 | E9: =COUNTIFS('Test case'!$B$5:$B$119,A9,'Test case'!$H$5:$H$119,"Chưa test") -> 0 | F9: =IF(B9=0,0,C9/B9) -> 1 | G9: =IF(B9=0,0,(C9+D9)/B9) -> 1
A10: Cổng công khai, session, cookie, AJAX, API | B10: =COUNTIF('Test case'!$B$5:$B$119,A10) -> 26 | C10: =COUNTIFS('Test case'!$B$5:$B$119,A10,'Test case'!$H$5:$H$119,"Pass") -> 23 | D10: =COUNTIFS('Test case'!$B$5:$B$119,A10,'Test case'!$H$5:$H$119,"Fail") -> 0 | E10: =COUNTIFS('Test case'!$B$5:$B$119,A10,'Test case'!$H$5:$H$119,"Chưa test") -> 3 | F10: =IF(B10=0,0,C10/B10) -> 0.88461538 | G10: =IF(B10=0,0,(C10+D10)/B10) -> 0.88461538
A11: Bảo mật và quốc tế hóa | B11: =COUNTIF('Test case'!$B$5:$B$119,A11) -> 10 | C11: =COUNTIFS('Test case'!$B$5:$B$119,A11,'Test case'!$H$5:$H$119,"Pass") -> 9 | D11: =COUNTIFS('Test case'!$B$5:$B$119,A11,'Test case'!$H$5:$H$119,"Fail") -> 0 | E11: =COUNTIFS('Test case'!$B$5:$B$119,A11,'Test case'!$H$5:$H$119,"Chưa test") -> 1 | F11: =IF(B11=0,0,C11/B11) -> 0.9 | G11: =IF(B11=0,0,(C11+D11)/B11) -> 0.9
A12: TỔNG CỘNG | B12: =SUM(B5:B11) -> 115 | C12: =SUM(C5:C11) -> 107 | D12: =SUM(D5:D11) -> 1 | E12: =SUM(E5:E11) -> 7 | F12: =IF(B12=0,0,C12/B12) -> 0.93043478 | G12: =IF(B12=0,0,(C12+D12)/B12) -> 0.93913043
A14: Số test case ưu tiên Cao | B14: =COUNTIF('Test case'!$K$5:$K$119,"Cao") -> 73
A15: Số test case ưu tiên Cao đã Pass | B15: =COUNTIFS('Test case'!$K$5:$K$119,"Cao",'Test case'!$H$5:$H$119,"Pass") -> 71
